<?xml version="1.0" encoding="UTF-8"?>
<!-- Generated by org.testng.reporters.JUnitReportReporter -->
<testsuite hostname="DESKTOP-8HN186T" failures="1" tests="1" name="testcases_signIn_up_accountsinfo_module.TC01_02_03_04_Accounts_Info" time="205.435" errors="0" timestamp="2024-12-10T22:59:17 IST" skipped="0">
  <testcase classname="testcases_signIn_up_accountsinfo_module.TC01_02_03_04_Accounts_Info" name="removerepair" time="205.435">
    <failure message="Failed due to this exception" type="java.lang.AssertionError">
      <![CDATA[java.lang.AssertionError: Failed due to this exception
at org.testng.Assert.fail(Assert.java:99)
at testcases_signIn_up_accountsinfo_module.TC01_02_03_04_Accounts_Info.pairBlewithoutRouter(TC01_02_03_04_Accounts_Info.java:95)
at testcases_signIn_up_accountsinfo_module.TC01_02_03_04_Accounts_Info.removerepair(TC01_02_03_04_Accounts_Info.java:52)
at java.base/jdk.internal.reflect.NativeMethodAccessorImpl.invoke0(Native Method)
at java.base/jdk.internal.reflect.NativeMethodAccessorImpl.invoke(NativeMethodAccessorImpl.java:77)
at java.base/jdk.internal.reflect.DelegatingMethodAccessorImpl.invoke(DelegatingMethodAccessorImpl.java:43)
at java.base/java.lang.reflect.Method.invoke(Method.java:568)
at org.testng.internal.invokers.MethodInvocationHelper.invokeMethod(MethodInvocationHelper.java:139)
at org.testng.internal.invokers.TestInvoker.invokeMethod(TestInvoker.java:664)
at org.testng.internal.invokers.TestInvoker.invokeTestMethod(TestInvoker.java:228)
at org.testng.internal.invokers.MethodRunner.runInSequence(MethodRunner.java:63)
at org.testng.internal.invokers.TestInvoker$MethodInvocationAgent.invoke(TestInvoker.java:961)
at org.testng.internal.invokers.TestInvoker.invokeTestMethods(TestInvoker.java:201)
at org.testng.internal.invokers.TestMethodWorker.invokeTestMethods(TestMethodWorker.java:148)
at org.testng.internal.invokers.TestMethodWorker.run(TestMethodWorker.java:128)
at java.base/java.util.ArrayList.forEach(ArrayList.java:1511)
at org.testng.TestRunner.privateRun(TestRunner.java:819)
at org.testng.TestRunner.run(TestRunner.java:619)
at org.testng.SuiteRunner.runTest(SuiteRunner.java:443)
at org.testng.SuiteRunner.runSequentially(SuiteRunner.java:437)
at org.testng.SuiteRunner.privateRun(SuiteRunner.java:397)
at org.testng.SuiteRunner.run(SuiteRunner.java:336)
at org.testng.SuiteRunnerWorker.runSuite(SuiteRunnerWorker.java:52)
at org.testng.SuiteRunnerWorker.run(SuiteRunnerWorker.java:95)
at org.testng.TestNG.runSuitesSequentially(TestNG.java:1301)
at org.testng.TestNG.runSuitesLocally(TestNG.java:1228)
at org.testng.TestNG.runSuites(TestNG.java:1134)
at org.testng.TestNG.run(TestNG.java:1101)
at org.testng.remote.AbstractRemoteTestNG.run(AbstractRemoteTestNG.java:115)
at org.testng.remote.RemoteTestNG.initAndRun(RemoteTestNG.java:293)
at org.testng.remote.RemoteTestNG.main(RemoteTestNG.java:91)
Caused by: java.lang.RuntimeException: FAILED
at utils.Reporter.reportStep(Reporter.java:46)
at wrappers.GenericWrappers.entervaluebyXpath(GenericWrappers.java:259)
at pages.AccountsInfoPage.enterOTPField1(AccountsInfoPage.java:173)
at pages.AccountsInfoPage.checkAccountsinfousername_email_Language(AccountsInfoPage.java:324)
at testcases_signIn_up_accountsinfo_module.TC01_02_03_04_Accounts_Info.pairBlewithoutRouter(TC01_02_03_04_Accounts_Info.java:88)
... 29 more
]]>
    </failure>
  </testcase> <!-- removerepair -->
</testsuite> <!-- testcases_signIn_up_accountsinfo_module.TC01_02_03_04_Accounts_Info -->
